2020-12-18 00:28:37 INFO: Start logging
2020-12-18 00:28:37 INFO: Default local config:
					file_server_host: 127.0.0.1
					file_server_port: 3223
					web_server_port: 8080
					root_login: root
					root_password: password
					settings_resuming: yes
					settings_web_enable: yes
					settings_log_file: log.txt
2020-12-18 00:40:42 INFO: Start logging
2020-12-18 00:40:42 INFO: Default local config:
					file_server_host: 127.0.0.1
					file_server_port: 3223
					web_server_port: 8080
					root_login: root
					root_password: password
					settings_resuming: yes
					settings_web_enable: yes
					settings_log_file: log.txt
2020-12-18 00:41:13 INFO: Start logging
2020-12-18 00:41:13 INFO: Default local config:
					file_server_host: 127.0.0.1
					file_server_port: 3223
					web_server_port: 8080
					root_login: root
					root_password: password
					settings_resuming: yes
					settings_web_enable: yes
					settings_log_file: log.txt
2020-12-18 00:41:13 INFO: Server started on 127.0.0.1:3223
2020-12-18 00:42:03 INFO: Connected to: 127.0.0.1:49924
2020-12-18 00:42:03 ERROR: Task exception was never retrieved
future: <Task finished name='Task-5' coro=<process() done, defined at D:\GitHub\Soft\File_Manager\src\Network.py:7> exception=NameError("name 'CommandFactory' is not defined")>
Traceback (most recent call last):
  File "D:\GitHub\Soft\File_Manager\src\Network.py", line 11, in process
    factory = CommandFactory(reader, writer)
NameError: name 'CommandFactory' is not defined
2020-12-18 01:08:06 INFO: Start logging
2020-12-18 01:08:06 INFO: Default local config:
					file_server_host: 127.0.0.1
					file_server_port: 3223
					web_server_port: 8080
					root_login: root
					root_password: password
					settings_resuming: yes
					settings_web_enable: yes
					settings_log_file: log.txt
2020-12-18 01:08:06 INFO: Server started on 127.0.0.1:3223
2020-12-18 01:08:25 INFO: Client 127.0.0.1:50202 is connected!
2020-12-18 01:08:25 ERROR: Task exception was never retrieved
future: <Task finished name='Task-5' coro=<process() done, defined at D:\GitHub\Soft\File_Manager\src\Network.py:9> exception=NameError("name 'CommandFactory' is not defined")>
Traceback (most recent call last):
  File "D:\GitHub\Soft\File_Manager\src\Network.py", line 13, in process
    factory = CommandFactory(reader, writer)
NameError: name 'CommandFactory' is not defined
2020-12-18 02:07:45 INFO: Start logging
2020-12-18 02:07:45 INFO: Default local config:
					file_server_host: 127.0.0.1
					file_server_port: 3223
					web_server_port: 8080
					root_login: root
					root_password: password
					settings_resuming: yes
					settings_web_enable: yes
					settings_log_file: log.txt
2020-12-18 02:07:45 INFO: Server started on 127.0.0.1:3223
2020-12-18 02:08:32 INFO: Client 127.0.0.1:50824 is connected!
2020-12-18 02:08:32 ERROR: Task exception was never retrieved
future: <Task finished name='Task-5' coro=<process() done, defined at D:\GitHub\Soft\File_Manager\src\Server.py:8> exception=TypeError('__init__() takes 1 positional argument but 3 were given')>
Traceback (most recent call last):
  File "D:\GitHub\Soft\File_Manager\src\Server.py", line 12, in process
    factory = CommandFactory(reader, writer)
TypeError: __init__() takes 1 positional argument but 3 were given
2020-12-18 02:12:10 INFO: Start logging
2020-12-18 02:12:10 INFO: Default local config:
					file_server_host: 127.0.0.1
					file_server_port: 3223
					web_server_port: 8080
					root_login: root
					root_password: password
					settings_resuming: yes
					settings_web_enable: yes
					settings_log_file: log.txt
2020-12-18 02:12:10 INFO: Server started on 127.0.0.1:3223
2020-12-18 02:14:35 INFO: Start logging
2020-12-18 02:14:35 INFO: Default local config:
					file_server_host: 127.0.0.1
					file_server_port: 3223
					web_server_port: 8080
					root_login: root
					root_password: password
					settings_resuming: yes
					settings_web_enable: yes
					settings_log_file: log.txt
2020-12-18 02:14:35 INFO: Server started on 127.0.0.1:3223
2020-12-18 02:14:54 INFO: Client 127.0.0.1:50880 is connected!
2020-12-18 02:14:54 ERROR: Task exception was never retrieved
future: <Task finished name='Task-5' coro=<process() done, defined at D:\GitHub\Soft\File_Manager\src\Server.py:8> exception=TypeError('__init__() takes 1 positional argument but 3 were given')>
Traceback (most recent call last):
  File "D:\GitHub\Soft\File_Manager\src\Server.py", line 12, in process
    factory = CommandFactory(reader, writer)
TypeError: __init__() takes 1 positional argument but 3 were given
2020-12-18 02:19:37 INFO: Start logging
2020-12-18 02:19:37 INFO: Default local config:
					file_server_host: 127.0.0.1
					file_server_port: 3223
					web_server_port: 8080
					root_login: root
					root_password: password
					settings_resuming: yes
					settings_web_enable: yes
					settings_log_file: log.txt
2020-12-18 02:19:37 INFO: Server started on 127.0.0.1:3223
2020-12-18 02:19:42 INFO: Client 127.0.0.1:50937 is connected!
2020-12-18 02:19:42 ERROR: Task exception was never retrieved
future: <Task finished name='Task-5' coro=<process() done, defined at D:\GitHub\Soft\File_Manager\src\Server.py:8> exception=TypeError('__init__() takes 1 positional argument but 3 were given')>
Traceback (most recent call last):
  File "D:\GitHub\Soft\File_Manager\src\Server.py", line 12, in process
    factory = CommandFactory(reader, writer)
TypeError: __init__() takes 1 positional argument but 3 were given
2020-12-18 02:20:51 INFO: Start logging
2020-12-18 02:20:51 INFO: Default local config:
					file_server_host: 127.0.0.1
					file_server_port: 3223
					web_server_port: 8080
					root_login: root
					root_password: password
					settings_resuming: yes
					settings_web_enable: yes
					settings_log_file: log.txt
2020-12-18 02:20:51 INFO: Server started on 127.0.0.1:3223
2020-12-18 02:20:59 INFO: Client 127.0.0.1:50944 is connected!
2020-12-18 02:21:07 ERROR: Task exception was never retrieved
future: <Task finished name='Task-5' coro=<process() done, defined at D:\GitHub\Soft\File_Manager\src\Server.py:8> exception=UnicodeDecodeError('utf-8', b"\xff\xfb\x1f\xff\xfb \xff\xfb\x18\xff\xfb'\xff\xfd\x01\xff\xfb\x03\xff\xfd\x03\r\n", 0, 1, 'invalid start byte')>
Traceback (most recent call last):
  File "D:\GitHub\Soft\File_Manager\src\Server.py", line 16, in process
    line = (await reader.readline()).decode().strip()
UnicodeDecodeError: 'utf-8' codec can't decode byte 0xff in position 0: invalid start byte
2020-12-18 02:23:06 INFO: Start logging
2020-12-18 02:23:06 INFO: Default local config:
					file_server_host: 127.0.0.1
					file_server_port: 3223
					web_server_port: 8080
					root_login: root
					root_password: password
					settings_resuming: yes
					settings_web_enable: yes
					settings_log_file: log.txt
2020-12-18 02:23:06 INFO: Server started on 127.0.0.1:3223
2020-12-18 02:23:16 INFO: Client 127.0.0.1:50961 is connected!
2020-12-18 02:23:24 ERROR: Task exception was never retrieved
future: <Task finished name='Task-5' coro=<process() done, defined at D:\GitHub\Soft\File_Manager\src\Server.py:8> exception=UnicodeDecodeError('utf-8', b"\xff\xfb\x1f\xff\xfb \xff\xfb\x18\xff\xfb'\xff\xfd\x01\xff\xfb\x03\xff\xfd\x03ECHO_START\r\n", 0, 1, 'invalid start byte')>
Traceback (most recent call last):
  File "D:\GitHub\Soft\File_Manager\src\Server.py", line 16, in process
    line = (await reader.readline()).decode().strip()
UnicodeDecodeError: 'utf-8' codec can't decode byte 0xff in position 0: invalid start byte
2020-12-18 02:31:14 INFO: Start logging
2020-12-18 02:31:14 INFO: Default local config:
					file_server_host: 127.0.0.1
					file_server_port: 3223
					web_server_port: 8080
					root_login: root
					root_password: password
					settings_resuming: yes
					settings_web_enable: yes
					settings_log_file: log.txt
2020-12-18 02:31:14 INFO: Server started on 127.0.0.1:3223
2020-12-18 02:31:24 INFO: Client 127.0.0.1:51060 is connected!
2020-12-18 02:31:27 ERROR: Task exception was never retrieved
future: <Task finished name='Task-5' coro=<process() done, defined at D:\GitHub\Soft\File_Manager\src\Server.py:8> exception=TypeError('__UnknownCommand() takes no arguments')>
Traceback (most recent call last):
  File "D:\GitHub\Soft\File_Manager\src\Server.py", line 17, in process
    command = factory.get_command(line)
  File "D:\GitHub\Soft\File_Manager\src\commands\CommandFactory.py", line 24, in get_command
    return self._commands.get(command, self.__UnknownCommand)(
TypeError: __UnknownCommand() takes no arguments
2020-12-18 02:33:19 INFO: Start logging
2020-12-18 02:33:19 INFO: Default local config:
					file_server_host: 127.0.0.1
					file_server_port: 3223
					web_server_port: 8080
					root_login: root
					root_password: password
					settings_resuming: yes
					settings_web_enable: yes
					settings_log_file: log.txt
2020-12-18 02:33:19 INFO: Server started on 127.0.0.1:3223
2020-12-18 02:33:27 INFO: Client 127.0.0.1:51079 is connected!
2020-12-18 02:33:27 ERROR: Task exception was never retrieved
future: <Task finished name='Task-5' coro=<process() done, defined at D:\GitHub\Soft\File_Manager\src\Server.py:8> exception=TypeError('__init__() takes 1 positional argument but 3 were given')>
Traceback (most recent call last):
  File "D:\GitHub\Soft\File_Manager\src\Server.py", line 12, in process
    factory = CommandFactory(reader, writer)
TypeError: __init__() takes 1 positional argument but 3 were given
2020-12-18 02:40:06 INFO: Start logging
2020-12-18 02:40:06 INFO: Default local config:
					file_server_host: 127.0.0.1
					file_server_port: 3223
					web_server_port: 8080
					root_login: root
					root_password: password
					settings_resuming: yes
					settings_web_enable: yes
					settings_log_file: log.txt
2020-12-18 02:40:06 INFO: Server started on 127.0.0.1:3223
2020-12-18 02:40:12 INFO: Client 127.0.0.1:51139 is connected!
2020-12-18 02:40:19 ERROR: Task exception was never retrieved
future: <Task finished name='Task-5' coro=<process() done, defined at D:\GitHub\Soft\File_Manager\src\Server.py:8> exception=AttributeError("'CommandFactory' object has no attribute 'commands'")>
Traceback (most recent call last):
  File "D:\GitHub\Soft\File_Manager\src\Server.py", line 17, in process
    command = factory.get_command(line)
  File "D:\GitHub\Soft\File_Manager\src\commands\CommandFactory.py", line 86, in get_command
    for command in self.commands:
AttributeError: 'CommandFactory' object has no attribute 'commands'
2020-12-18 02:42:01 INFO: Start logging
2020-12-18 02:42:01 INFO: Default local config:
					file_server_host: 127.0.0.1
					file_server_port: 3223
					web_server_port: 8080
					root_login: root
					root_password: password
					settings_resuming: yes
					settings_web_enable: yes
					settings_log_file: log.txt
2020-12-18 02:42:01 INFO: Server started on 127.0.0.1:3223
2020-12-18 02:42:02 INFO: Start logging
2020-12-18 02:42:02 INFO: Default local config:
					file_server_host: 127.0.0.1
					file_server_port: 3223
					web_server_port: 8080
					root_login: root
					root_password: password
					settings_resuming: yes
					settings_web_enable: yes
					settings_log_file: log.txt
2020-12-18 02:42:02 INFO: Server started on 127.0.0.1:3223
2020-12-18 02:42:07 INFO: Client 127.0.0.1:51162 is connected!
2020-12-18 02:42:14 ERROR: Task exception was never retrieved
future: <Task finished name='Task-5' coro=<process() done, defined at D:\GitHub\Soft\File_Manager\src\Server.py:8> exception=TypeError("object NoneType can't be used in 'await' expression")>
Traceback (most recent call last):
  File "D:\GitHub\Soft\File_Manager\src\Server.py", line 18, in process
    await command.execute()
TypeError: object NoneType can't be used in 'await' expression
2020-12-18 03:00:19 INFO: Start logging
2020-12-18 03:00:19 INFO: Default local config:
					file_server_host: 127.0.0.1
					file_server_port: 3223
					web_server_port: 8080
					root_login: root
					root_password: password
					settings_resuming: yes
					settings_web_enable: yes
					settings_log_file: log.txt
2020-12-18 03:00:19 INFO: Server started on 127.0.0.1:3223
2020-12-18 03:00:25 INFO: Client 127.0.0.1:51378 is connected!
2020-12-18 03:00:25 ERROR: Task exception was never retrieved
future: <Task finished name='Task-5' coro=<process() done, defined at D:\GitHub\Soft\File_Manager\src\Server.py:8> exception=AttributeError("can't set attribute")>
Traceback (most recent call last):
  File "D:\GitHub\Soft\File_Manager\src\Server.py", line 12, in process
    factory = CommandFactory(reader, writer)
  File "D:\GitHub\Soft\File_Manager\src\commands\CommandFactory.py", line 75, in __init__
    self.commands = [
AttributeError: can't set attribute
2020-12-18 03:01:30 INFO: Start logging
2020-12-18 03:01:30 INFO: Default local config:
					file_server_host: 127.0.0.1
					file_server_port: 3223
					web_server_port: 8080
					root_login: root
					root_password: password
					settings_resuming: yes
					settings_web_enable: yes
					settings_log_file: log.txt
2020-12-18 03:01:30 INFO: Server started on 127.0.0.1:3223
2020-12-18 03:01:34 INFO: Client 127.0.0.1:51388 is connected!
2020-12-18 03:01:36 ERROR: Task exception was never retrieved
future: <Task finished name='Task-5' coro=<process() done, defined at D:\GitHub\Soft\File_Manager\src\Server.py:8> exception=TypeError("object NoneType can't be used in 'await' expression")>
Traceback (most recent call last):
  File "D:\GitHub\Soft\File_Manager\src\Server.py", line 18, in process
    await command.execute()
TypeError: object NoneType can't be used in 'await' expression
2020-12-18 03:01:57 INFO: Start logging
2020-12-18 03:01:57 INFO: Default local config:
					file_server_host: 127.0.0.1
					file_server_port: 3223
					web_server_port: 8080
					root_login: root
					root_password: password
					settings_resuming: yes
					settings_web_enable: yes
					settings_log_file: log.txt
2020-12-18 03:01:57 INFO: Server started on 127.0.0.1:3223
2020-12-18 03:02:04 INFO: Client 127.0.0.1:51396 is connected!
2020-12-18 03:02:07 ERROR: Task exception was never retrieved
future: <Task finished name='Task-5' coro=<process() done, defined at D:\GitHub\Soft\File_Manager\src\Server.py:8> exception=TypeError("object NoneType can't be used in 'await' expression")>
Traceback (most recent call last):
  File "D:\GitHub\Soft\File_Manager\src\Server.py", line 18, in process
    await command.execute()
TypeError: object NoneType can't be used in 'await' expression
2020-12-18 03:02:34 INFO: Start logging
2020-12-18 03:02:34 INFO: Default local config:
					file_server_host: 127.0.0.1
					file_server_port: 3223
					web_server_port: 8080
					root_login: root
					root_password: password
					settings_resuming: yes
					settings_web_enable: yes
					settings_log_file: log.txt
2020-12-18 03:02:34 INFO: Server started on 127.0.0.1:3223
2020-12-18 03:02:38 INFO: Client 127.0.0.1:51402 is connected!
2020-12-18 03:02:40 ERROR: Task exception was never retrieved
future: <Task finished name='Task-5' coro=<process() done, defined at D:\GitHub\Soft\File_Manager\src\Server.py:8> exception=TypeError("object NoneType can't be used in 'await' expression")>
Traceback (most recent call last):
  File "D:\GitHub\Soft\File_Manager\src\Server.py", line 18, in process
    await command.execute()
TypeError: object NoneType can't be used in 'await' expression
2020-12-18 03:04:40 INFO: Start logging
2020-12-18 03:04:40 INFO: Default local config:
					file_server_host: 127.0.0.1
					file_server_port: 3223
					web_server_port: 8080
					root_login: root
					root_password: password
					settings_resuming: yes
					settings_web_enable: yes
					settings_log_file: log.txt
2020-12-18 03:04:40 INFO: Server started on 127.0.0.1:3223
2020-12-18 03:04:44 INFO: Client 127.0.0.1:51479 is connected!
2020-12-18 03:04:48 ERROR: Task exception was never retrieved
future: <Task finished name='Task-5' coro=<process() done, defined at D:\GitHub\Soft\File_Manager\src\Server.py:8> exception=AttributeError("'bytes' object has no attribute 'encode'")>
Traceback (most recent call last):
  File "D:\GitHub\Soft\File_Manager\src\Server.py", line 16, in process
    line = (await reader.readline()).encode('utf-8').decode('utf-8').strip()
AttributeError: 'bytes' object has no attribute 'encode'
2020-12-18 03:05:12 INFO: Start logging
2020-12-18 03:05:12 INFO: Default local config:
					file_server_host: 127.0.0.1
					file_server_port: 3223
					web_server_port: 8080
					root_login: root
					root_password: password
					settings_resuming: yes
					settings_web_enable: yes
					settings_log_file: log.txt
2020-12-18 03:05:12 INFO: Server started on 127.0.0.1:3223
2020-12-18 03:05:17 INFO: Client 127.0.0.1:51485 is connected!
2020-12-18 03:05:19 ERROR: Task exception was never retrieved
future: <Task finished name='Task-5' coro=<process() done, defined at D:\GitHub\Soft\File_Manager\src\Server.py:8> exception=UnicodeDecodeError('utf-8', b"\xff\xfb\x1f\xff\xfb \xff\xfb\x18\xff\xfb'\xff\xfd\x01\xff\xfb\x03\xff\xfd\x03a\r\n", 0, 1, 'invalid start byte')>
Traceback (most recent call last):
  File "D:\GitHub\Soft\File_Manager\src\Server.py", line 16, in process
    line = (await reader.readline()).decode('utf-8').strip()
UnicodeDecodeError: 'utf-8' codec can't decode byte 0xff in position 0: invalid start byte
2020-12-18 03:08:37 INFO: Start logging
2020-12-18 03:08:37 INFO: Default local config:
					file_server_host: 127.0.0.1
					file_server_port: 3223
					web_server_port: 8080
					root_login: root
					root_password: password
					settings_resuming: yes
					settings_web_enable: yes
					settings_log_file: log.txt
2020-12-18 03:08:37 INFO: Server started on 127.0.0.1:3223
2020-12-18 03:08:46 INFO: Client 127.0.0.1:51555 is connected!
2020-12-18 03:08:49 ERROR: Task exception was never retrieved
future: <Task finished name='Task-5' coro=<process() done, defined at D:\GitHub\Soft\File_Manager\src\Server.py:8> exception=TypeError("object NoneType can't be used in 'await' expression")>
Traceback (most recent call last):
  File "D:\GitHub\Soft\File_Manager\src\Server.py", line 18, in process
    await command.execute()
TypeError: object NoneType can't be used in 'await' expression
2020-12-18 03:09:34 INFO: Start logging
2020-12-18 03:09:34 INFO: Default local config:
					file_server_host: 127.0.0.1
					file_server_port: 3223
					web_server_port: 8080
					root_login: root
					root_password: password
					settings_resuming: yes
					settings_web_enable: yes
					settings_log_file: log.txt
2020-12-18 03:09:34 INFO: Server started on 127.0.0.1:3223
2020-12-18 03:09:50 INFO: Client 127.0.0.1:51564 is connected!
2020-12-18 03:09:52 ERROR: Task exception was never retrieved
future: <Task finished name='Task-5' coro=<process() done, defined at D:\GitHub\Soft\File_Manager\src\Server.py:8> exception=TypeError("object NoneType can't be used in 'await' expression")>
Traceback (most recent call last):
  File "D:\GitHub\Soft\File_Manager\src\Server.py", line 18, in process
    await command.execute()
TypeError: object NoneType can't be used in 'await' expression
